Workbook

Sheet PL
B2: Tata Motors
B3: Standalone Profit & Loss account
C4: 44256 | D4: 44621 | E4: 44986 | F4: 45352 | G4: 45717
C6: 12 mths | D6: 12 mths | E6: 12 mths | F6: 12 mths | G6: 12 mths
B8: INCOME
B9: Revenue From Operations [Gross] | C9: 29769.07 | D9: 46880.97 | E9: 65298.84 | F9: 72745.92 | G9: 68869
B10: Revenue From Operations [Net] | C10: 29769.07 | D10: 46880.97 | E10: 65298.84 | F10: 72745.92 | G10: 68869
B11: Other Operating Revenues | C11: 405.96 | D11: 382.71 | E11: 458.49 | F11: 557.16 | G11: 550
B12: Total Operating Revenues | C12: 30175.03 | D12: 47263.68 | E12: 65757.33 | F12: 73303.08 | G12: 69419
B13: Other Income | C13: 419.99 | D13: 659.91 | E13: 820.94 | F13: 1149.88 | G13: 2796
B14: Total Revenue | C14: 30595.02 | D14: 47923.59 | E14: 66578.27 | F14: 74452.96 | G14: 72215
B15: EXPENSES
B16: Cost Of Materials Consumed | C16: 19050.74 | D16: 31693.11 | E16: 42226.81 | F16: 45025.05 | G16: 39865
B17: Purchase Of Stock-In Trade | C17: 3156.8 | D17: 5030 | E17: 6561.32 | F17: 7764.19 | G17: 7367
B18: Operating And Direct Expenses | C18: 348.71 | D18: 593.9 | E18: 899.06 | F18: 1104.79 | G18: 1033
B19: Changes In Inventories Of FG,WIP And Stock-In Trade | C19: -609.55 | D19: -403.87 | E19: 484.69 | F19: -600.44 | G19: 284
B20: Employee Benefit Expenses | C20: 3341.53 | D20: 3601.51 | E20: 4021.63 | F20: 4308.15 | G20: 4513
B21: Finance Costs | C21: 2110.83 | D21: 2121.73 | E21: 2047.51 | F21: 1705.74 | G21: 1122
B22: Depreciation And Amortisation Expenses | C22: 1730.71 | D22: 1760.57 | E22: 1766.86 | F22: 2016.84 | G22: 2008
B23: Other Expenses | C23: 4227.35 | D23: 6155.52 | E23: 8099.5 | F23: 9215.96 | G23: 9559
B24: Less: Amounts Transfer To Capital Accounts | C24: 794.93 | D24: 905.42 | E24: 1066.73 | F24: 1129.73 | G24: 1213
B25: Total Expenses | C25: 32562.19 | D25: 49647.05 | E25: 65040.65 | F25: 69410.55 | G25: 64538
C26: 44256 | D26: 44621 | E26: 44986 | F26: 45352 | G26: 45717
C28: 12 mths | D28: 12 mths | E28: 12 mths | F28: 12 mths | G28: 12 mths
B30: Profit/Loss Before Exceptional, ExtraOrdinary Items And Tax | C30: -1967.17 | D30: -1723.46 | E30: 1537.62 | F30: 5042.41 | G30: 7677
B31: Exceptional Items | C31: -307.55 | D31: 83.41 | E31: -282.82 | F31: 2808.41 | G31: -325
B32: Profit/Loss Before Tax | C32: -2274.72 | D32: -1640.05 | E32: 1254.8 | F32: 7850.82 | G32: 7352
B33: Tax Expenses-Continued Operations
B34: Current Tax | C34: 20.16 | D34: 51.18 | E34: 81.6 | F34: 114.22 | G34: 53
B35: Deferred Tax | C35: 0.56 | D35: 48 | E35: -1554.93 | F35: -165.48 | G35: 1847
B36: Total Tax Expenses | C36: 20.72 | D36: 99.18 | E36: -1473.33 | F36: -51.26 | G36: 1900
B37: Profit/Loss After Tax And Before ExtraOrdinary Items | C37: -2295.44 | D37: -1739.23 | E37: 2728.13 | F37: 7902.08 | G37: 5452
B38: Profit/Loss From Continuing Operations | C38: -2295.44 | D38: -1739.23 | E38: 2728.13 | F38: 7902.08 | G38: 5452
B39: Profit Loss From Discontinuing Operations | C39: -37.85 | D39: 392.51 | E39: 0 | F39: 0 | G39: 0
B40: Total Tax Expenses Discontinuing Operations | C40: 62.15 | D40: 44.14 | E40: 0 | F40: 0 | G40: 0
B41: Net Profit Loss From Discontinuing Operations | C41: -100 | D41: 348.37 | E41: 0 | F41: 0 | G41: 0
B42: Profit/Loss For The Period | C42: -2395.44 | D42: -1390.86 | E42: 2728.13 | F42: 7902.08 | G42: 5452
C43: 44256 | D43: 44621 | E43: 44986 | F43: 45352 | G43: 45717
C45: 12 mths | D45: 12 mths | E45: 12 mths | F45: 12 mths | G45: 12 mths
B47: OTHER ADDITIONAL INFORMATION
...

Sheet BS
B3: Standalone Balance Sheet | G3: ------------------- in Rs. Cr. -------------------
C4: 44256 | D4: 44621 | E4: 44986 | F4: 45352 | G4: 45741
C6: 12 mths | D6: 12 mths | E6: 12 mths | F6: 12 mths | G6: 12 mths
B8: EQUITIES AND LIABILITIES
B9: SHAREHOLDER'S FUNDS
B10: Equity Share Capital | C10: 765.81 | D10: 765.88 | E10: 766.02 | F10: 766.5 | G10: 736
B11: Total Share Capital | C11: 765.81 | D11: 765.88 | E11: 766.02 | F11: 766.5 | G11: 736
B12: Reserves and Surplus | C12: 18290.16 | D12: 19171.88 | E12: 21701.37 | F12: 29374.83 | G12: 32705
B13: Total Reserves and Surplus | C13: 18290.16 | D13: 19171.88 | E13: 21701.37 | F13: 29374.83 | G13: 32705
B14: Total Shareholders Funds | C14: 19055.97 | D14: 19937.76 | E14: 22467.39 | F14: 30141.33 | G14: 33441
B15: Equity Share Application Money | C15: 0 | D15: 6.39 | E15: 2.46 | F15: 1.72 | G15: 1
B16: NON-CURRENT LIABILITIES
B17: Long Term Borrowings | C17: 16326.77 | D17: 14102.74 | E17: 10445.7 | F17: 5235.67 | G17: 3626
B18: Deferred Tax Liabilities [Net] | C18: 266.5 | D18: 173.72 | E18: 51.16 | F18: 49.78 | G18: 404
B19: Other Long Term Liabilities | C19: 1786.93 | D19: 1212.34 | E19: 1411.78 | F19: 1392.16 | G19: 1302
B20: Long Term Provisions | C20: 1371.94 | D20: 1474.11 | E20: 1588.75 | F20: 1936.92 | G20: 2222
B21: Total Non-Current Liabilities | C21: 19752.14 | D21: 16962.91 | E21: 13497.39 | F21: 8614.53 | G21: 7554
B22: CURRENT LIABILITIES
B23: Short Term Borrowings | C23: 5421.95 | D23: 9129.91 | E23: 8426.74 | F23: 8535.37 | G23: 4982
B24: Trade Payables | C24: 8115.01 | D24: 6102.1 | E24: 7162.6 | F24: 8826.46 | G24: 13267
B25: Other Current Liabilities | C25: 11671.05 | D25: 11152.74 | E25: 9805.3 | F25: 8830.41 | G25: 4040
B26: Short Term Provisions | C26: 1043.54 | D26: 608.06 | E26: 408.89 | F26: 1133.92 | G26: 2135
B27: Total Current Liabilities | C27: 26251.55 | D27: 26992.81 | E27: 25803.53 | F27: 27326.16 | G27: 24424
B28: Total Capital And Liabilities | C28: 65059.66 | D28: 63899.87 | E28: 61770.77 | F28: 66083.74 | G28: 65420
B29: ASSETS
B30: NON-CURRENT ASSETS
B31: Tangible Assets | C31: 19922.06 | D31: 12065.89 | E31: 12129.14 | F31: 11990.26 | G31: 12188
B32: Intangible Assets | C32: 6501.04 | D32: 2009.87 | E32: 2413.18 | F32: 2353.79 | G32: 1927
B33: Capital Work-In-Progress | C33: 1400.82 | D33: 585.21 | E33: 575.65 | F33: 645.03 | G33: 683
B34: Intangible Assets Under Development | C34: 1605.64 | D34: 882.03 | E34: 509.3 | F34: 588.92 | G34: 1141
B35: Fixed Assets | C35: 29429.56 | D35: 15543 | E35: 15627.27 | F35: 15578 | G35: 15939
B36: Non-Current Investments | C36: 16114.91 | D36: 29256.39 | E36: 29181.62 | F36: 30315.57 | G36: 31427
B37: Deferred Tax Assets [Net] | C37: 0 | D37: 0 | E37: 1477.26 | F37: 1558.65 | G37: 0
B38: Long Term Loans And Advances | C38: 72.39 | D38: 48.43 | E38: 114.4 | F38: 101.89 | G38: 255
B39: Other Non-Current Assets | C39: 3588.21 | D39: 3432.44 | E39: 3870.27 | F39: 3321.96 | G39: 2899
B40: Total Non-Current Assets | C40: 49205.07 | D40: 48280.26 | E40: 50270.82 | F40: 50876.07 | G40: 50520
B41: CURRENT ASSETS
B42: Current Investments | C42: 1578.26 | D42: 5143.08 | E42: 3142.96 | F42: 1993.5 | G42: 2857
B43: Inventories | C43: 4551.71 | D43: 3718.49 | E43: 3027.9 | F43: 3470.38 | G43: 3154
B44: Trade Receivables | C44: 2087.51 | D44: 2111.78 | E44: 2307.72 | F44: 2765.16 | G44: 2280
...

Sheet P&L assumptions 
A1: Tata Motors
A2: Standalone Profit & Loss account | B2: Historical Data | G2: FORECASTED DATA
B3: 44256 | C3: 44621 | D3: 44986 | E3: 45352 | F3: 45717 | G3: 46082 | H3: 46447 | I3: 46813 | J3: 47178 | K3: 47543
A4: =PL!B8 -> INCOME
A5: =PL!B10 -> Revenue From Operations [Net] | B5: =PL!C10 -> 29769.07 | C5: =PL!D10 -> 46880.97 | D5: =PL!E10 -> 65298.84 | E5: =PL!F10 -> 72745.92 | F5: =PL!G10 -> 68869 | G5: =(F5+(G6*F5)) -> 79282.375 | H5: =(G5+(H6*G5)) -> 91270.311 | I5: =(H5+(I6*H5)) -> 105070.89 | J5: =(I5+(J6*I5)) -> 120958.19 | K5: =(J5+(K6*J5)) -> 139247.74
A6: YoY Growth | C6: =(C5-B5)/B5 -> 0.57482145 | D6: =(D5-C5)/C5 -> 0.39286452 | E6: =(E5-D5)/D5 -> 0.11404613 | F6: =(F5-E5)/E5 -> -0.053293985 | G6: =AVERAGE($D$6:$F$6) -> 0.15120556 | H6: =AVERAGE($D$6:$F$6) -> 0.15120556 | I6: =AVERAGE($D$6:$F$6) -> 0.15120556 | J6: =AVERAGE($D$6:$F$6) -> 0.15120556 | K6: =AVERAGE($D$6:$F$6) -> 0.15120556
A7: =PL!B11 -> Other Operating Revenues | B7: =PL!C11 -> 405.96 | C7: =PL!D11 -> 382.71 | D7: =PL!E11 -> 458.49 | E7: =PL!F11 -> 557.16 | F7: =PL!G11 -> 550 | G7: =G8*G5 -> 599.01994 | H7: =H8*H5 -> 689.59509 | I7: =I8*I5 -> 793.8657 | J7: =J8*J5 -> 913.9026 | K7: =K8*K5 -> 1052.0898
A8: Percentage of sales | B8: =B7/B5 -> 0.013636973 | C8: =C7/C5 -> 0.0081634403 | D8: =D7/D5 -> 0.0070214111 | E8: =E7/E5 -> 0.0076589862 | F8: =F7/F5 -> 0.0079861767 | G8: =AVERAGE($D$8:$F$8) -> 0.0075555247 | H8: =AVERAGE($D$8:$F$8) -> 0.0075555247 | I8: =AVERAGE($D$8:$F$8) -> 0.0075555247 | J8: =AVERAGE($D$8:$F$8) -> 0.0075555247 | K8: =AVERAGE($D$8:$F$8) -> 0.0075555247
A9: =PL!B12 -> Total Operating Revenues | B9: =B5+B7 -> 30175.03 | C9: =C5+C7 -> 47263.68 | D9: =D5+D7 -> 65757.33 | E9: =E5+E7 -> 73303.08 | F9: =F5+F7 -> 69419 | G9: =G5+G7 -> 79881.395 | H9: =H5+H7 -> 91959.906 | I9: =I5+I7 -> 105864.76 | ... K9: =K5+K7 -> 140299.83
A10: EXPENSES
A11: Cost of goods Sold | B11: =SUM(PL!C16:C19) -> 21946.7 | C11: =SUM(PL!D16:D19) -> 36913.14 | D11: =SUM(PL!E16:E19) -> 50171.88 | E11: =SUM(PL!F16:F19) -> 53293.59 | F11: =SUM(PL!G16:G19) -> 48549 | G11: =G12*G5 -> 58296.032 | H11: =H12*H5 -> 67110.716 | I11: =I12*I5 -> 77258.229 | J11: =J12*J5 -> 88940.102 | K11: =K12*K5 -> 102388.34
A12: =A8 -> Percentage of sales | B12: =B11/B5 -> 0.73723163 | C12: =C11/C5 -> 0.78738004 | D12: =D11/D5 -> 0.76834259 | E12: =E11/E5 -> 0.73259902 | F12: =F11/F5 -> 0.70494707 | G12: =AVERAGE($D$12:$F$12) -> 0.73529623 | H12: =AVERAGE($D$12:$F$12) -> 0.73529623 | I12: =AVERAGE($D$12:$F$12) -> 0.73529623 | J12: =AVERAGE($D$12:$F$12) -> 0.73529623 | K12: =AVERAGE($D$12:$F$12) -> 0.73529623
A13: Gross Profit | B13: =B9-B11 -> 8228.33 | C13: =C9-C11 -> 10350.54 | D13: =D9-D11 -> 15585.45 | E13: =E9-E11 -> 20009.49 | F13: =F9-F11 -> 20870 | G13: =G9-G11 -> 21585.364 | H13: =H9-H11 -> 24849.191 | I13: =I9-I11 -> 28606.526 | ... K13: =K9-K11 -> 37911.492
A14: =PL!B20 -> Employee Benefit Expenses | B14: =PL!C20 -> 3341.53 | C14: =PL!D20 -> 3601.51 | D14: =PL!E20 -> 4021.63 | E14: =PL!F20 -> 4308.15 | F14: =PL!G20 -> 4513 | G14: =G15*G5 -> 4924.497 | H14: =H15*H5 -> 5669.1083 | I14: =I15*I5 -> 6526.3089 | J14: =J15*J5 -> 7513.1231 | K14: =K15*K5 -> 8649.1491
A15: =A12 -> Percentage of sales | B15: =B14/B5 -> 0.11224838 | C15: =C14/C5 -> 0.076822429 | D15: =D14/D5 -> 0.061588077 | E15: =E14/E5 -> 0.059221878 | F15: =F14/F5 -> 0.06553021 | G15: =AVERAGE($D$15:$F$15) -> 0.062113388 | H15: =AVERAGE($D$15:$F$15) -> 0.062113388 | I15: =AVERAGE($D$15:$F$15) -> 0.062113388 | J15: =AVERAGE($D$15:$F$15) -> 0.062113388 | K15: =AVERAGE($D$15:$F$15) -> 0.062113388
A16: =PL!B23 -> Other Expenses | B16: =PL!C23-PL!C24 -> 3432.42 | C16: =PL!D23-PL!D24 -> 5250.1 | D16: =PL!E23-PL!E24 -> 7032.77 | E16: =PL!F23-PL!F24 -> 8086.23 | F16: =PL!G23-PL!G24 -> 8346 | G16: =G17*G5 -> 8986.5268 | H16: =H17*H5 -> 10345.34 | I16: =I17*I5 -> 11909.612 | J16: =J17*J5 -> 13710.412 | K16: =K17*K5 -> 15783.502
A17: =A15 -> Percentage of sales | B17: =B16/B5 -> 0.11530155 | C17: =C16/C5 -> 0.11198787 | D17: =D16/D5 -> 0.1077013 | E17: =E16/E5 -> 0.11115716 | F17: =F16/F5 -> 0.1211866 | G17: =AVERAGE($D$17:$F$17) -> 0.11334835 | H17: =AVERAGE($D$17:$F$17) -> 0.11334835 | I17: =AVERAGE($D$17:$F$17) -> 0.11334835 | J17: =AVERAGE($D$17:$F$17) -> 0.11334835 | K17: =AVERAGE($D$17:$F$17) -> 0.11334835
A18: EBITDA | B18: =B13-B14-B16 -> 1454.38 | C18: =C13-C14-C16 -> 1498.93 | D18: =D13-D14-D16 -> 4531.05 | E18: =E13-E14-E16 -> 7615.11 | F18: =F13-F14-F16 -> 8011 | G18: =G13-G14-G16 -> 7674.3399 | H18: =H13-H14-H16 -> 8834.7427 | I18: =I13-I14-I16 -> 10170.605 | ... K18: =K13-K14-K16 -> 13478.841
A19: =PL!B22 -> Depreciation And Amortisation Expenses | B19: =PL!C22 -> 1730.71 | C19: =PL!D22 -> 1760.57 | D19: =PL!E22 -> 1766.86 | E19: =PL!F22 -> 2016.84 | F19: =PL!G22 -> 2008 | G19: =G20*G5 -> 2218.3026 | H19: =H20*H5 -> 2553.7222 | I19: =I20*I5 -> 2939.8592 | J19: =J20*J5 -> 3384.3823 | K19: =K20*K5 -> 3896.1197
A20: =A17 -> Percentage of sales | B20: =B19/B5 -> 0.058137859 | C20: =C19/C5 -> 0.037554044 | D20: =D19/D5 -> 0.027058061 | E20: =E19/E5 -> 0.027724441 | F20: =F19/F5 -> 0.029156805 | G20: =AVERAGE($D$20:$F$20) -> 0.027979769 | H20: =AVERAGE($D$20:$F$20) -> 0.027979769 | I20: =AVERAGE($D$20:$F$20) -> 0.027979769 | J20: =AVERAGE($D$20:$F$20) -> 0.027979769 | K20: =AVERAGE($D$20:$F$20) -> 0.027979769
A21: EBIT | B21: =B18-B19 -> -276.33 | C21: =C18-C19 -> -261.64 | D21: =D18-D19 -> 2764.19 | E21: =E18-E19 -> 5598.27 | F21: =F18-F19 -> 6003 | G21: =G18-G19 -> 5456.0373 | H21: =H18-H19 -> 6281.0205 | I21: =I18-I19 -> 7230.7457 | ... K21: =K18-K19 -> 9582.7209
A22: =PL!B21 -> Finance Costs | B22: =PL!C21 -> 2110.83 | C22: =PL!D21 -> 2121.73 | D22: =PL!E21 -> 2047.51 | E22: =PL!F21 -> 1705.74 | F22: =PL!G21 -> 1122 | G22: =G23*G5 -> 1878.8788 | H22: =H23*H5 -> 2162.9758 | I22: =I23*I5 -> 2490.0297 | J22: =J23*J5 -> 2866.536 | K22: =K23*K5 -> 3299.9722
A23: =A20 -> Percentage of sales | B23: =B22/B5 -> 0.070906817 | C23: =C22/C5 -> 0.045257809 | D23: =D22/D5 -> 0.031355993 | E23: =E22/E5 -> 0.023447913 | F23: =F22/F5 -> 0.0162918 | G23: =AVERAGE($D$23:$F$23) -> 0.023698569 | H23: =AVERAGE($D$23:$F$23) -> 0.023698569 | I23: =AVERAGE($D$23:$F$23) -> 0.023698569 | J23: =AVERAGE($D$23:$F$23) -> 0.023698569 | K23: =AVERAGE($D$23:$F$23) -> 0.023698569
A24: =PL!B13 -> Other Income | B24: =PL!C13 -> 419.99 | C24: =PL!D13 -> 659.91 | D24: =PL!E13 -> 820.94 | E24: =PL!F13 -> 1149.88 | F24: =PL!G13 -> 2796 | G24: =AVERAGE($D$24:$F$24) -> 1588.94 | H24: =AVERAGE($D$24:$F$24) -> 1588.94 | I24: =AVERAGE($D$24:$F$24) -> 1588.94 | J24: =AVERAGE($D$24:$F$24) -> 1588.94 | K24: =AVERAGE($D$24:$F$24) -> 1588.94
A25: EBT(BEFORE EXCEPTIONAL ITEMS) | B25: =B21-B22+B24 -> -1967.17 | C25: =C21-C22+C24 -> -1723.46 | D25: =D21-D22+D24 -> 1537.62 | E25: =E21-E22+E24 -> 5042.41 | F25: =F21-F22+F24 -> 7677 | G25: =G21-G22+G24 -> 5166.0985 | H25: =H21-H22+H24 -> 5706.9847 | I25: =I21-I22+I24 -> 6329.6559 | ... K25: =K21-K22+K24 -> 7871.6887
A26: =PL!B31 -> Exceptional Items | B26: =PL!C31 -> -307.55 | C26: =PL!D31 -> 83.41 | D26: =PL!E31 -> -282.82 | E26: =PL!F31 -> 2808.41 | F26: =PL!G31 -> -325 | G26: =PL!H31 -> 0 | H26: =PL!I31 -> 0 | ... K26: =PL!L31 -> 0
A27: EBT | B27: =B25+B26 -> -2274.72 | C27: =C25+C26 -> -1640.05 | D27: =D25+D26 -> 1254.8 | E27: =E25+E26 -> 7850.82 | F27: =F25+F26 -> 7352 | G27: =G25+G26 -> 5166.0985 | H27: =H25+H26 -> 5706.9847 | I27: =I25+I26 -> 6329.6559 | ... K27: =K25+K26 -> 7871.6887
A28: =PL!B36 -> Total Tax Expenses | B28: =PL!C36 -> 20.72 | C28: =PL!D36 -> 99.18 | D28: =PL!E36 -> -1473.33 | E28: =PL!F36 -> -51.26 | F28: =PL!G36 -> 1900 | G28: =G29*G27 -> 1291.5246 | H28: =H29*H27 -> 1426.7462 | I28: =I29*I27 -> 1582.414 | J28: =J29*J27 -> 1761.6196 | K28: =K29*K27 -> 1967.9222
A29: Tax rate | B29: =B28/B27 -> -0.0091088134 | C29: =C28/C27 -> -0.060473766 | D29: =D28/D27 -> -1.1741552 | E29: =E28/E27 -> -0.0065292543 | F29: =F28/F27 -> 0.25843308 | G29: 0.25 | H29: 0.25 | I29: 0.25 | J29: 0.25 | K29: 0.25
A30: PAT ( FROM CONTINUED OPERATIONS) | B30: =B27-B28 -> -2295.44 | C30: =C27-C28 -> -1739.23 | D30: =D27-D28 -> 2728.13 | E30: =E27-E28 -> 7902.08 | F30: =F27-F28 -> 5452 | G30: =G27-G28 -> 3874.5738 | H30: =H27-H28 -> 4280.2385 | I30: =I27-I28 -> 4747.242 | ... K30: =K27-K28 -> 5903.7665

Sheet Balance sheet Assumption 
B2: Tata Motors
B3: Standalone Balance Sheet | C3: Historical Data | H3: FORECASTED DATA
B4: =BS!B8 -> EQUITIES AND LIABILITIES | C4: 44256 | D4: 44621 | E4: 44986 | F4: 45352 | G4: 45717 | H4: 46082 | I4: 46447 | J4: 46813 | K4: 47178 | L4: 47543
B5: =BS!B9 -> SHAREHOLDER'S FUNDS
B6: =BS!B14 -> Total Shareholders Funds | C6: =BS!C14 -> 19055.97 | D6: =BS!D14 -> 19937.76 | E6: =BS!E14 -> 22467.39 | F6: =BS!F14 -> 30141.33 | G6: =BS!G14 -> 33441 | H6: =G6+'P&L assumptions '!G30 -> 37315.574 | I6: =H6+'P&L assumptions '!H30 -> 41595.812 | J6: =I6+'P&L assumptions '!I30 -> 46343.054 | K6: =J6+'P&L assumptions '!J30 -> 51627.913 | L6: =K6+'P&L assumptions '!K30 -> 57531.68
B7: Last year TSF+ CY Profit
B8: =BS!B15 -> Equity Share Application Money | C8: =BS!C15 -> 0 | D8: =BS!D15 -> 6.39 | E8: =BS!E15 -> 2.46 | F8: =BS!F15 -> 1.72 | G8: =BS!G15 -> 1 | H8: =BS!H15 -> 0 | I8: =BS!I15 -> 0 | ... L8: =BS!L15 -> 0
B9: =BS!B16 -> NON-CURRENT LIABILITIES
B10: =BS!B17 -> Long Term Borrowings | C10: =BS!C17 -> 16326.77 | D10: =BS!D17 -> 14102.74 | E10: =BS!E17 -> 10445.7 | F10: =BS!F17 -> 5235.67 | G10: =BS!G17 -> 3626 | H10: =H11*H6 -> 9292.3361 | I10: =I11*I6 -> 10358.202 | J10: =J11*J6 -> 11540.362 | K10: =K11*K6 -> 12856.399 | L10: =L11*L6 -> 14326.557
B11: Percentage of TSF | C11: =C10/C6 -> 0.85677979 | D11: =D10/D6 -> 0.70733824 | E11: =E10/E6 -> 0.46492717 | F11: =F10/F6 -> 0.17370401 | G11: =G10/G6 -> 0.10842977 | H11: =AVERAGE($E$11:$G$11) -> 0.24902032 | I11: =AVERAGE($E$11:$G$11) -> 0.24902032 | J11: =AVERAGE($E$11:$G$11) -> 0.24902032 | K11: =AVERAGE($E$11:$G$11) -> 0.24902032 | L11: =AVERAGE($E$11:$G$11) -> 0.24902032
B12: =BS!B18 -> Deferred Tax Liabilities [Net] | C12: =BS!C18 -> 266.5 | D12: =BS!D18 -> 173.72 | E12: =BS!E18 -> 51.16 | F12: =BS!F18 -> 49.78 | G12: =BS!G18 -> 404 | H12: =BS!H18 -> 0 | I12: =BS!I18 -> 0 | ... L12: =BS!L18 -> 0
B13: No assumptions required
B14: =BS!B19 -> Other Long Term Liabilities | C14: =BS!C19 -> 1786.93 | D14: =BS!D19 -> 1212.34 | E14: =BS!E19 -> 1411.78 | F14: =BS!F19 -> 1392.16 | G14: =BS!G19 -> 1302 | H14: =H15*H6 -> 1840.3896 | I14: =I15*I6 -> 2051.4893 | J14: =J15*J6 -> 2285.6214 | K14: =K15*K6 -> 2546.2686 | L14: =L15*L6 -> 2837.4401
B15: =B11 -> Percentage of TSF | C15: =C14/C6 -> 0.093772713 | D15: =D14/D6 -> 0.060806229 | E15: =E14/E6 -> 0.062836849 | F15: =F14/F6 -> 0.046187743 | G15: =G14/G6 -> 0.038934242 | H15: =AVERAGE($E$15:$G$15) -> 0.049319612 | I15: =AVERAGE($E$15:$G$15) -> 0.049319612 | J15: =AVERAGE($E$15:$G$15) -> 0.049319612 | K15: =AVERAGE($E$15:$G$15) -> 0.049319612 | L15: =AVERAGE($E$15:$G$15) -> 0.049319612
B16: =BS!B20 -> Long Term Provisions | C16: =BS!C20 -> 1371.94 | D16: =BS!D20 -> 1474.11 | E16: =BS!E20 -> 1588.75 | F16: =BS!F20 -> 1936.92 | G16: =BS!G20 -> 2222 | H16: =H17*H6 -> 2505.3707 | I16: =I17*I6 -> 2792.7462 | J16: =J17*J6 -> 3111.4765 | K16: =K17*K6 -> 3466.3023 | L16: =L17*L6 -> 3862.6817
B17: =B15 -> Percentage of TSF | C17: =C16/C6 -> 0.071995285 | D17: =D16/D6 -> 0.073935588 | E17: =E16/E6 -> 0.070713599 | F17: =F16/F6 -> 0.064261265 | G17: =G16/G6 -> 0.066445381 | H17: =AVERAGE($E$17:$G$17) -> 0.067140082 | I17: =AVERAGE($E$17:$G$17) -> 0.067140082 | J17: =AVERAGE($E$17:$G$17) -> 0.067140082 | K17: =AVERAGE($E$17:$G$17) -> 0.067140082 | L17: =AVERAGE($E$17:$G$17) -> 0.067140082
B18: =BS!B21 -> Total Non-Current Liabilities | C18: =C10+C12+C14+C16 -> 19752.14 | D18: =D10+D12+D14+D16 -> 16962.91 | E18: =E10+E12+E14+E16 -> 13497.39 | F18: =F10+F12+F14+F16 -> 8614.53 | G18: =G10+G12+G14+G16 -> 7554 | H18: =H10+H12+H14+H16 -> 13638.096 | I18: =I10+I12+I14+I16 -> 15202.438 | J18: =J10+J12+J14+J16 -> 16937.46 | ... L18: =L10+L12+L14+L16 -> 21026.679
B19: =BS!B22 -> CURRENT LIABILITIES
B20: =BS!B23 -> Short Term Borrowings | C20: =BS!C23 -> 5421.95 | D20: =BS!D23 -> 9129.91 | E20: =BS!E23 -> 8426.74 | F20: =BS!F23 -> 8535.37 | G20: =BS!G23 -> 4982 | H20: =H21*'P&L assumptions '!G5 -> 8422.9686 | I20: =I21*'P&L assumptions '!H5 -> 9696.5682 | J20: =J21*'P&L assumptions '!I5 -> 11162.743 | K20: =K21*'P&L assumptions '!J5 -> 12850.612 | L20: =L21*'P&L assumptions '!K5 -> 14793.696
B21: Percentage of Sales | C21: =C20/'P&L assumptions '!B5 -> 0.18213367 | D21: =D20/'P&L assumptions '!C5 -> 0.19474661 | E21: =E20/'P&L assumptions '!D5 -> 0.12904885 | F21: =F20/'P&L assumptions '!E5 -> 0.11733125 | G21: =G20/'P&L assumptions '!F5 -> 0.07234024 | H21: =AVERAGE($E$21:$G$21) -> 0.10624011 | I21: =AVERAGE($E$21:$G$21) -> 0.10624011 | J21: =AVERAGE($E$21:$G$21) -> 0.10624011 | K21: =AVERAGE($E$21:$G$21) -> 0.10624011 | L21: =AVERAGE($E$21:$G$21) -> 0.10624011
B22: =BS!B24 -> Trade Payables | C22: =BS!C24 -> 8115.01 | D22: =BS!D24 -> 6102.1 | E22: =BS!E24 -> 7162.6 | F22: =BS!F24 -> 8826.46 | G22: =BS!G24 -> 13267 | H22: =(H23*'P&L assumptions '!G11)/365 -> 11302.65 | I22: =(I23*'P&L assumptions '!H11)/365 -> 13011.674 | J22: =(J23*'P&L assumptions '!I11)/365 -> 14979.111 | K22: =(K23*'P&L assumptions '!J11)/365 -> 17244.036 | L22: =(L23*'P&L assumptions '!K11)/365 -> 19851.43
B23: Days Payable | C23: =(C22/'P&L assumptions '!B11)*365 -> 134.96237 | D23: =(D22/'P&L assumptions '!C11)*365 -> 60.33804 | E23: =(E22/'P&L assumptions '!D11)*365 -> 52.107854 | F23: =(F22/'P&L assumptions '!E11)*365 -> 60.451133 | G23: =(G22/'P&L assumptions '!F11)*365 -> 99.743661 | H23: =AVERAGE($E$23:$G$23) -> 70.767549 | I23: =AVERAGE($E$23:$G$23) -> 70.767549 | J23: =AVERAGE($E$23:$G$23) -> 70.767549 | K23: =AVERAGE($E$23:$G$23) -> 70.767549 | L23: =AVERAGE($E$23:$G$23) -> 70.767549
B24: =BS!B25 -> Other Current Liabilities | C24: =BS!C25 -> 11671.05 | D24: =BS!D25 -> 11152.74 | E24: =BS!E25 -> 9805.3 | F24: =BS!F25 -> 8830.41 | G24: =BS!G25 -> 4040 | H24: =H25*'P&L assumptions '!G5 -> 8726.5982 | I24: =I25*'P&L assumptions '!H5 -> 10046.108 | J24: =J25*'P&L assumptions '!I5 -> 11565.136 | K24: =K25*'P&L assumptions '!J5 -> 13313.848 | L24: =L25*'P&L assumptions '!K5 -> 15326.976
B25: Percentage of Sales | C25: =C24/'P&L assumptions '!B5 -> 0.39205289 | D25: =D24/'P&L assumptions '!C5 -> 0.23789482 | E25: =E24/'P&L assumptions '!D5 -> 0.1501604 | F25: =F24/'P&L assumptions '!E5 -> 0.12138701 | G25: =G24/'P&L assumptions '!F5 -> 0.058662098 | H25: =AVERAGE($E$25:$G$25) -> 0.11006984 | I25: =AVERAGE($E$25:$G$25) -> 0.11006984 | J25: =AVERAGE($E$25:$G$25) -> 0.11006984 | K25: =AVERAGE($E$25:$G$25) -> 0.11006984 | L25: =AVERAGE($E$25:$G$25) -> 0.11006984
B26: =BS!B26 -> Short Term Provisions | C26: =BS!C26 -> 1043.54 | D26: =BS!D26 -> 608.06 | E26: =BS!E26 -> 408.89 | F26: =BS!F26 -> 1133.92 | G26: =BS!G26 -> 2135 | H26: =H27*'P&L assumptions '!G5 -> 1396.6942 | I26: =I27*'P&L assumptions '!H5 -> 1607.8822 | J26: =J27*'P&L assumptions '!I5 -> 1851.0029 | K26: =K27*'P&L assumptions '!J5 -> 2130.8848 | L26: =L27*'P&L assumptions '!K5 -> 2453.0864
B27: =B25 -> Percentage of Sales | C27: =C26/'P&L assumptions '!B5 -> 0.035054505 | D27: =D26/'P&L assumptions '!C5 -> 0.012970295 | E27: =E26/'P&L assumptions '!D5 -> 0.0062618264 | F27: =F26/'P&L assumptions '!E5 -> 0.015587403 | G27: =G26/'P&L assumptions '!F5 -> 0.031000886 | H27: =AVERAGE($E$27:$G$27) -> 0.017616705 | I27: =AVERAGE($E$27:$G$27) -> 0.017616705 | J27: =AVERAGE($E$27:$G$27) -> 0.017616705 | K27: =AVERAGE($E$27:$G$27) -> 0.017616705 | L27: =AVERAGE($E$27:$G$27) -> 0.017616705
B28: =BS!B27 -> Total Current Liabilities | C28: =C26+C24+C22+C20 -> 26251.55 | D28: =D26+D24+D22+D20 -> 26992.81 | E28: =E26+E24+E22+E20 -> 25803.53 | F28: =F26+F24+F22+F20 -> 27326.16 | G28: =G26+G24+G22+G20 -> 24424 | H28: =H26+H24+H22+H20 -> 29848.911 | I28: =I26+I24+I22+I20 -> 34362.232 | J28: =J26+J24+J22+J20 -> 39557.993 | ... L28: =L26+L24+L22+L20 -> 52425.189
B29: =BS!B28 -> Total Capital And Liabilities | C29: =C28+C18+C8+C6 -> 65059.66 | D29: =D28+D18+D8+D6 -> 63899.87 | E29: =E28+E18+E8+E6 -> 61770.77 | F29: =F28+F18+F8+F6 -> 66083.74 | G29: =G28+G18+G8+G6 -> 65420 | H29: =H28+H18+H8+H6 -> 80802.581 | I29: =I28+I18+I8+I6 -> 91160.483 | J29: =J28+J18+J8+J6 -> 102838.51 | ... L29: =L28+L18+L8+L6 -> 130983.55
B31: =BS!B29 -> ASSETS
B32: =BS!B30 -> NON-CURRENT ASSETS
B33: =BS!B35 -> Fixed Assets | C33: =BS!C35 -> 29429.56 | D33: =BS!D35 -> 15543 | E33: =BS!E35 -> 15627.27 | F33: =BS!F35 -> 15578 | G33: =BS!G35 -> 15939 | H33: =H35*'P&L assumptions '!G5 -> 18100.199 | I33: =I35*'P&L assumptions '!H5 -> 20837.05 | J33: =J35*'P&L assumptions '!I5 -> 23987.728 | K33: =K35*'P&L assumptions '!J5 -> 27614.806 | L33: =L35*'P&L assumptions '!K5 -> 31790.318
B34: Percentage of TSF | C34: =C33/C6 -> 1.5443748 | D34: =D33/D6 -> 0.77957604 | E34: =E33/E6 -> 0.69555342 | F34: =F33/F6 -> 0.51683187 | G34: =G33/G6 -> 0.47663048
B35: Percentage of sales | C35: =C33/'P&L assumptions '!B5 -> 0.98859521 | D35: =D33/'P&L assumptions '!C5 -> 0.33154177 | E35: =E33/'P&L assumptions '!D5 -> 0.23931926 | F35: =F33/'P&L assumptions '!E5 -> 0.21414259 | G35: =G33/'P&L assumptions '!F5 -> 0.2314394 | H35: =AVERAGE($E$35:$G$35) -> 0.22830042 | I35: =AVERAGE($E$35:$G$35) -> 0.22830042 | J35: =AVERAGE($E$35:$G$35) -> 0.22830042 | K35: =AVERAGE($E$35:$G$35) -> 0.22830042 | L35: =AVERAGE($E$35:$G$35) -> 0.22830042
B36: =BS!B36 -> Non-Current Investments | C36: =BS!C36 -> 16114.91 | D36: =BS!D36 -> 29256.39 | E36: =BS!E36 -> 29181.62 | F36: =BS!F36 -> 30315.57 | G36: =BS!G36 -> 31427 | H36: =H37*H6 -> 40355.532 | I36: =I37*I6 -> 44984.466 | J36: =J37*J6 -> 50118.447 | K36: =K37*K6 -> 55833.844 | L36: =L37*L6 -> 62218.568
B37: =B34 -> Percentage of TSF | C37: =(C36/C6) -> 0.84566202 | D37: =(D36/D6) -> 1.467386 | E37: =(E36/E6) -> 1.2988433 | F37: =(F36/F6) -> 1.0057808 | G37: =(G36/G6) -> 0.93977453 | H37: =AVERAGE($E$37:$G$37) -> 1.0814662 | I37: =AVERAGE($E$37:$G$37) -> 1.0814662 | J37: =AVERAGE($E$37:$G$37) -> 1.0814662 | K37: =AVERAGE($E$37:$G$37) -> 1.0814662 | L37: =AVERAGE($E$37:$G$37) -> 1.0814662
B38: =BS!B37 -> Deferred Tax Assets [Net] | C38: =BS!C37 -> 0 | D38: =BS!D37 -> 0 | E38: =BS!E37 -> 1477.26 | F38: =BS!F37 -> 1558.65 | G38: =BS!G37 -> 0 | H38: =BS!H37 -> 0 | I38: =BS!I37 -> 0 | ... L38: =BS!L37 -> 0
B39: No Assumptions
B40: =BS!B38 -> Long Term Loans And Advances | C40: =BS!C38 -> 72.39 | D40: =BS!D38 -> 48.43 | E40: =BS!E38 -> 114.4 | F40: =BS!F38 -> 101.89 | G40: =BS!G38 -> 255 | H40: =H41*H6 -> 200.23042 | I40: =I41*I6 -> 223.19762 | J40: =J41*J6 -> 248.67069 | K40: =K41*K6 -> 277.02854 | L40: =L41*L6 -> 308.70737
B41: =B34 -> Percentage of TSF | C41: =C40/C6 -> 0.0037988095 | D41: =D40/D6 -> 0.0024290592 | E41: =E40/E6 -> 0.0050918242 | F41: =F40/F6 -> 0.0033804082 | G41: =G40/G6 -> 0.0076253701 | H41: =AVERAGE($E$41:$G$41) -> 0.0053658675 | I41: =AVERAGE($E$41:$G$41) -> 0.0053658675 | J41: =AVERAGE($E$41:$G$41) -> 0.0053658675 | K41: =AVERAGE($E$41:$G$41) -> 0.0053658675 | L41: =AVERAGE($E$41:$G$41) -> 0.0053658675
B42: =BS!B39 -> Other Non-Current Assets | C42: =BS!C39 -> 3588.21 | D42: =BS!D39 -> 3432.44 | E42: =BS!E39 -> 3870.27 | F42: =BS!F39 -> 3321.96 | G42: =BS!G39 -> 2899 | H42: =H43*H6 -> 4591.861 | I42: =I43*I6 -> 5118.565 | J42: =J43*J6 -> 5702.736 | K42: =K43*K6 -> 6353.0633 | L42: =L43*L6 -> 7079.5502
...

Sheet FREE CASH FLOW
B2: Tata Motors
C3: Historical Data | H3: FORECASTED DATA
B4: Calculation of Free Cash Flow | C4: 44256 | D4: 44621 | E4: 44986 | F4: 45352 | G4: 45717 | H4: 46082 | I4: 46447 | J4: 46813 | K4: 47178 | L4: 47543
B5: ='P&L assumptions '!A21 -> EBIT | C5: ='P&L assumptions '!B21 -> -276.33 | D5: ='P&L assumptions '!C21 -> -261.64 | E5: ='P&L assumptions '!D21 -> 2764.19 | F5: ='P&L assumptions '!E21 -> 5598.27 | G5: ='P&L assumptions '!F21 -> 6003 | H5: ='P&L assumptions '!G21 -> 5456.0373 | I5: ='P&L assumptions '!H21 -> 6281.0205 | ... L5: ='P&L assumptions '!K21 -> 9582.7209
B6: Tax | C6: =C7*C5 -> -69.0825 | D6: =D7*D5 -> -65.41 | E6: =E7*E5 -> 691.0475 | F6: =F7*F5 -> 1399.5675 | G6: =G7*G5 -> 1500.75 | H6: =H7*H5 -> 1364.0093 | I6: =I7*I5 -> 1570.2551 | J6: =J7*J5 -> 1807.6864 | ... L6: =L7*L5 -> 2395.6802
B7: Tax rate | C7: =$H$7 -> 0.25 | D7: =$H$7 -> 0.25 | E7: =$H$7 -> 0.25 | F7: =$H$7 -> 0.25 | G7: =$H$7 -> 0.25 | H7: 0.25 | I7: 0.25 | J7: 0.25 | K7: 0.25 | L7: 0.25
B8: NOPAT | C8: =C5-C6 -> -207.2475 | D8: =D5-D6 -> -196.23 | E8: =E5-E6 -> 2073.1425 | F8: =F5-F6 -> 4198.7025 | G8: =G5-G6 -> 4502.25 | H8: =H5-H6 -> 4092.028 | I8: =I5-I6 -> 4710.7653 | J8: =J5-J6 -> 5423.0592 | ... L8: =L5-L6 -> 7187.0407
B9: ='P&L assumptions '!A19 -> Depreciation And Amortisation Expenses | C9: ='P&L assumptions '!B19 -> 1730.71 | D9: ='P&L assumptions '!C19 -> 1760.57 | E9: ='P&L assumptions '!D19 -> 1766.86 | F9: ='P&L assumptions '!E19 -> 2016.84 | G9: ='P&L assumptions '!F19 -> 2008 | H9: ='P&L assumptions '!G19 -> 2218.3026 | I9: ='P&L assumptions '!H19 -> 2553.7222 | ... L9: ='P&L assumptions '!K19 -> 3896.1197
B10: Gross Cash Flow | C10: =C8+C9 -> 1523.4625 | D10: =D8+D9 -> 1564.34 | E10: =E8+E9 -> 3840.0025 | F10: =F8+F9 -> 6215.5425 | G10: =G8+G9 -> 6510.25 | H10: =H8+H9 -> 6310.3305 | I10: =I8+I9 -> 7264.4876 | J10: =J8+J9 -> 8362.9185 | ... L10: =L8+L9 -> 11083.16
B11: Capex | D11: ='Balance sheet Assumption '!D33-'Balance sheet Assumption '!C33+'P&L assumptions '!C19 -> -12125.99 | E11: ='Balance sheet Assumption '!E33-'Balance sheet Assumption '!D33+'P&L assumptions '!D19 -> 1851.13 | F11: ='Balance sheet Assumption '!F33-'Balance sheet Assumption '!E33+'P&L assumptions '!E19 -> 1967.57 | G11: ='Balance sheet Assumption '!G33-'Balance sheet Assumption '!F33+'P&L assumptions '!F19 -> 2369 | H11: ='Balance sheet Assumption '!H33-'Balance sheet Assumption '!G33+'P&L assumptions '!G19 -> 4379.502 | I11: ='Balance sheet Assumption '!I33-'Balance sheet Assumption '!H33+'P&L assumptions '!H19 -> 5290.573 | J11: ='Balance sheet Assumption '!J33-'Balance sheet Assumption '!I33+'P&L assumptions '!I19 -> 6090.537 | K11: ='Balance sheet Assumption '!K33-'Balance sheet Assumption '!J33+'P&L assumptions '!J19 -> 7011.46 | L11: ='Balance sheet Assumption '!L33-'Balance sheet Assumption '!K33+'P&L assumptions '!K19 -> 8071.6317
B12: Changes in Working capital
B13: ='Balance sheet Assumption '!B20 -> Short Term Borrowings | D13: ='Balance sheet Assumption '!D20-'Balance sheet Assumption '!C20 -> 3707.96 | E13: ='Balance sheet Assumption '!E20-'Balance sheet Assumption '!D20 -> -703.17 | F13: ='Balance sheet Assumption '!F20-'Balance sheet Assumption '!E20 -> 108.63 | G13: ='Balance sheet Assumption '!G20-'Balance sheet Assumption '!F20 -> -3553.37 | H13: ='Balance sheet Assumption '!H20-'Balance sheet Assumption '!G20 -> 3440.9686 | I13: ='Balance sheet Assumption '!I20-'Balance sheet Assumption '!H20 -> 1273.5997 | J13: ='Balance sheet Assumption '!J20-'Balance sheet Assumption '!I20 -> 1466.175 | K13: ='Balance sheet Assumption '!K20-'Balance sheet Assumption '!J20 -> 1687.8688 | L13: ='Balance sheet Assumption '!L20-'Balance sheet Assumption '!K20 -> 1943.0839
B14: ='Balance sheet Assumption '!B22 -> Trade Payables | D14: ='Balance sheet Assumption '!D22-'Balance sheet Assumption '!C22 -> -2012.91 | E14: ='Balance sheet Assumption '!E22-'Balance sheet Assumption '!D22 -> 1060.5 | F14: ='Balance sheet Assumption '!F22-'Balance sheet Assumption '!E22 -> 1663.86 | G14: ='Balance sheet Assumption '!G22-'Balance sheet Assumption '!F22 -> 4440.54 | H14: ='Balance sheet Assumption '!H22-'Balance sheet Assumption '!G22 -> -1964.3498 | I14: ='Balance sheet Assumption '!I22-'Balance sheet Assumption '!H22 -> 1709.0235 | J14: ='Balance sheet Assumption '!J22-'Balance sheet Assumption '!I22 -> 1967.4374 | K14: ='Balance sheet Assumption '!K22-'Balance sheet Assumption '!J22 -> 2264.9248 | L14: ='Balance sheet Assumption '!L22-'Balance sheet Assumption '!K22 -> 2607.394
B15: ='Balance sheet Assumption '!B24 -> Other Current Liabilities | D15: ='Balance sheet Assumption '!D24-'Balance sheet Assumption '!C24 -> -518.31 | E15: ='Balance sheet Assumption '!E24-'Balance sheet Assumption '!D24 -> -1347.44 | F15: ='Balance sheet Assumption '!F24-'Balance sheet Assumption '!E24 -> -974.89 | G15: ='Balance sheet Assumption '!G24-'Balance sheet Assumption '!F24 -> -4790.41 | H15: ='Balance sheet Assumption '!H24-'Balance sheet Assumption '!G24 -> 4686.5982 | I15: ='Balance sheet Assumption '!I24-'Balance sheet Assumption '!H24 -> 1319.5101 | J15: ='Balance sheet Assumption '!J24-'Balance sheet Assumption '!I24 -> 1519.0274 | K15: ='Balance sheet Assumption '!K24-'Balance sheet Assumption '!J24 -> 1748.7128 | L15: ='Balance sheet Assumption '!L24-'Balance sheet Assumption '!K24 -> 2013.1279
B16: ='Balance sheet Assumption '!B26 -> Short Term Provisions | D16: ='Balance sheet Assumption '!D26-'Balance sheet Assumption '!C26 -> -435.48 | E16: ='Balance sheet Assumption '!E26-'Balance sheet Assumption '!D26 -> -199.17 | F16: ='Balance sheet Assumption '!F26-'Balance sheet Assumption '!E26 -> 725.03 | G16: ='Balance sheet Assumption '!G26-'Balance sheet Assumption '!F26 -> 1001.08 | H16: ='Balance sheet Assumption '!H26-'Balance sheet Assumption '!G26 -> -738.30577 | I16: ='Balance sheet Assumption '!I26-'Balance sheet Assumption '!H26 -> 211.18793 | J16: ='Balance sheet Assumption '!J26-'Balance sheet Assumption '!I26 -> 243.12072 | K16: ='Balance sheet Assumption '!K26-'Balance sheet Assumption '!J26 -> 279.88192 | L16: ='Balance sheet Assumption '!L26-'Balance sheet Assumption '!K26 -> 322.20162
B17: ='Balance sheet Assumption '!B48 -> Inventories | D17: ='Balance sheet Assumption '!D48-'Balance sheet Assumption '!C48 -> -833.22 | E17: ='Balance sheet Assumption '!E48-'Balance sheet Assumption '!D48 -> -690.59 | F17: ='Balance sheet Assumption '!F48-'Balance sheet Assumption '!E48 -> 442.48 | G17: ='Balance sheet Assumption '!G48-'Balance sheet Assumption '!F48 -> -316.38 | H17: ='Balance sheet Assumption '!H48-'Balance sheet Assumption '!G48 -> 546.51516 | I17: ='Balance sheet Assumption '!I48-'Balance sheet Assumption '!H48 -> 559.53845 | J17: ='Balance sheet Assumption '!J48-'Balance sheet Assumption '!I48 -> 644.14378 | K17: ='Balance sheet Assumption '!K48-'Balance sheet Assumption '!J48 -> 741.54189 | L17: ='Balance sheet Assumption '!L48-'Balance sheet Assumption '!K48 -> 853.66715
B18: ='Balance sheet Assumption '!B50 -> Trade Receivables | D18: ='Balance sheet Assumption '!D50-'Balance sheet Assumption '!C50 -> 24.27 | E18: ='Balance sheet Assumption '!E50-'Balance sheet Assumption '!D50 -> 195.94 | F18: ='Balance sheet Assumption '!F50-'Balance sheet Assumption '!E50 -> 457.44 | G18: ='Balance sheet Assumption '!G50-'Balance sheet Assumption '!F50 -> -485.16 | H18: ='Balance sheet Assumption '!H50-'Balance sheet Assumption '!G50 -> 533.426 | I18: ='Balance sheet Assumption '!I50-'Balance sheet Assumption '!H50 -> 425.40564 | J18: ='Balance sheet Assumption '!J50-'Balance sheet Assumption '!I50 -> 489.72934 | K18: ='Balance sheet Assumption '!K50-'Balance sheet Assumption '!J50 -> 563.77914 | L18: ='Balance sheet Assumption '!L50-'Balance sheet Assumption '!K50 -> 649.02568
B19: ='Balance sheet Assumption '!B54 -> Short Term Loans And Advances | D19: ='Balance sheet Assumption '!D54-'Balance sheet Assumption '!C54 -> -45.12 | E19: ='Balance sheet Assumption '!E54-'Balance sheet Assumption '!D54 -> -7.08 | F19: ='Balance sheet Assumption '!F54-'Balance sheet Assumption '!E54 -> -0.1 | G19: ='Balance sheet Assumption '!G54-'Balance sheet Assumption '!F54 -> 2927.81 | H19: ='Balance sheet Assumption '!H54-'Balance sheet Assumption '!G54 -> -1784.2079 | I19: ='Balance sheet Assumption '!I54-'Balance sheet Assumption '!H54 -> 192.90685 | J19: ='Balance sheet Assumption '!J54-'Balance sheet Assumption '!I54 -> 222.07544 | K19: ='Balance sheet Assumption '!K54-'Balance sheet Assumption '!J54 -> 255.65448 | L19: ='Balance sheet Assumption '!L54-'Balance sheet Assumption '!K54 -> 294.31085
B20: ='Balance sheet Assumption '!B56 -> OtherCurrentAssets | D20: ='Balance sheet Assumption '!D56-'Balance sheet Assumption '!C56 -> -1232.22 | E20: ='Balance sheet Assumption '!E56-'Balance sheet Assumption '!D56 -> -427.03 | F20: ='Balance sheet Assumption '!F56-'Balance sheet Assumption '!E56 -> 221.05 | G20: ='Balance sheet Assumption '!G56-'Balance sheet Assumption '!F56 -> 252.52 | H20: ='Balance sheet Assumption '!H56-'Balance sheet Assumption '!G56 -> 12.182395 | I20: ='Balance sheet Assumption '!I56-'Balance sheet Assumption '!H56 -> 296.39047 | J20: ='Balance sheet Assumption '!J56-'Balance sheet Assumption '!I56 -> 341.20636 | K20: ='Balance sheet Assumption '!K56-'Balance sheet Assumption '!J56 -> 392.79865 | L20: ='Balance sheet Assumption '!L56-'Balance sheet Assumption '!K56 -> 452.19199
B21: NET CHANGES IN WORKING CAPITAL | D21: =(SUM(D13:D16)-(SUM(D17:D20))) -> 2827.55 | E21: =(SUM(E13:E16)-(SUM(E17:E20))) -> -260.52 | F21: =(SUM(F13:F16)-(SUM(F17:F20))) -> 401.76 | G21: =(SUM(G13:G16)-(SUM(G17:G20))) -> -5280.95 | H21: =(SUM(H13:H16)-(SUM(H17:H20))) -> 6116.9955 | I21: =(SUM(I13:I16)-(SUM(I17:I20))) -> 3039.0798 | J21: =(SUM(J13:J16)-(SUM(J17:J20))) -> 3498.6056 | K21: =(SUM(K13:K16)-(SUM(K17:K20))) -> 4027.6142 | L21: =(SUM(L13:L16)-(SUM(L17:L20))) -> 4636.6118
B22: FREE CASH FLOW OF THE FIRM | D22: =D10-D11+D21 -> 16517.88 | E22: =E10-E11+E21 -> 1728.3525 | F22: =F10-F11+F21 -> 4649.7325 | G22: =G10-G11+G21 -> -1139.7 | H22: =H10-H11+H21 -> 8047.8241 | I22: =I10-I11+I21 -> 5012.9944 | J22: =J10-J11+J21 -> 5770.987 | K22: =K10-K11+K21 -> 6643.5923 | L22: =L10-L11+L21 -> 7648.1404

Sheet WACC
B2: CALCULATION OF WACC
B4: CALCULATION OF COST OF DEBT
C5: 44256 | D5: 44621 | E5: 44986 | F5: 45352 | G5: 45717
B6: ='P&L assumptions '!A22 -> Finance Costs | C6: ='P&L assumptions '!B22 -> 2110.83 | D6: ='P&L assumptions '!C22 -> 2121.73 | E6: ='P&L assumptions '!D22 -> 2047.51 | F6: ='P&L assumptions '!E22 -> 1705.74 | G6: ='P&L assumptions '!F22 -> 1122
B8: ='Balance sheet Assumption '!B20 -> Short Term Borrowings | C8: ='Balance sheet Assumption '!C20 -> 5421.95 | D8: ='Balance sheet Assumption '!D20 -> 9129.91 | E8: ='Balance sheet Assumption '!E20 -> 8426.74 | F8: ='Balance sheet Assumption '!F20 -> 8535.37 | G8: ='Balance sheet Assumption '!G20 -> 4982
B9: ='Balance sheet Assumption '!B10 -> Long Term Borrowings | C9: ='Balance sheet Assumption '!C10 -> 16326.77 | D9: ='Balance sheet Assumption '!D10 -> 14102.74 | E9: ='Balance sheet Assumption '!E10 -> 10445.7 | F9: ='Balance sheet Assumption '!F10 -> 5235.67 | G9: ='Balance sheet Assumption '!G10 -> 3626
B10: TOTAL BORROWINGS | C10: =C8+C9 -> 21748.72 | D10: =D8+D9 -> 23232.65 | E10: =E8+E9 -> 18872.44 | F10: =F8+F9 -> 13771.04 | G10: =G8+G9 -> 8608
B12: Cost of debt | C12: =C6/C10 -> 0.097055367 | D12: =D6/D10 -> 0.091325355 | E12: =E6/E10 -> 0.10849207 | F12: =F6/F10 -> 0.12386428 | G12: =G6/G10 -> 0.13034387
B13: Tax rate | C13: 0.25
B15: Average Cost of Debt | C15: =AVERAGE($E$12:$G$12) -> 0.12090007
B16: Average cost of debt( after Tax) | C16: =C15*(1-C13) -> 0.090675054
B18: CALCULATION OF COST OF EQUITY
C19: ='Balance sheet Assumption '!C4 -> 44256 | D19: ='Balance sheet Assumption '!D4 -> 44621 | E19: ='Balance sheet Assumption '!E4 -> 44986 | F19: ='Balance sheet Assumption '!F4 -> 45352 | G19: ='Balance sheet Assumption '!G4 -> 45717
B20: ='Balance sheet Assumption '!B6 -> Total Shareholders Funds | C20: ='Balance sheet Assumption '!C6 -> 19055.97 | D20: ='Balance sheet Assumption '!D6 -> 19937.76 | E20: ='Balance sheet Assumption '!E6 -> 22467.39 | F20: ='Balance sheet Assumption '!F6 -> 30141.33 | G20: ='Balance sheet Assumption '!G6 -> 33441
B21: Cost of Equity (CAPM) | C21: =6.88%+1.82*(7.31%-6.88%) -> 0.076626
B23: Equity :Debt | C23: =C20/C10 -> 0.87618812 | D23: =D20/D10 -> 0.85817847 | E23: =E20/E10 -> 1.1904868 | F23: =F20/F10 -> 2.1887475 | G23: =G20/G10 -> 3.8848745
B25: WACC | C25: =((((C20/(C20+C10))*$C$21)+((C10/(C10+C20))*$C$16))) -> 0.084114084 | D25: =((((D20/(D20+D10))*$C$21)+((D10/(D10+D20))*$C$16))) -> 0.084186659 | E25: =((((E20/(E20+E10))*$C$21)+((E10/(E10+E20))*$C$16))) -> 0.083039668 | F25: =((((F20/(F20+F10))*$C$21)+((F10/(F10+F20))*$C$16))) -> 0.081031822 | G25: =((((G20/(G20+G10))*$C$21)+((G10/(G10+G20))*$C$16))) -> 0.079502032
B26: Average WACC | C26: =AVERAGE($E$25:$G$25) -> 0.081191174

Sheet Ev & Sesnsitivity Analysis
D1: ENTERPRISE VALUE & SENSITIVITY ANALYSIS
B3: =WACC!B26 -> Average WACC | C3: =WACC!C26 -> 0.081191174
B4: Terminal Growth Rate (g) | C4: 0.05 | G4: 1 | H4: 2 | I4: 3 | J4: 4 | K4: 5
G5: ='FREE CASH FLOW'!H4 -> 46082 | H5: ='FREE CASH FLOW'!I4 -> 46447 | I5: ='FREE CASH FLOW'!J4 -> 46813 | J5: ='FREE CASH FLOW'!K4 -> 47178 | K5: ='FREE CASH FLOW'!L4 -> 47543
F6: ='FREE CASH FLOW'!B22 -> FREE CASH FLOW OF THE FIRM | G6: ='FREE CASH FLOW'!H22 -> 8047.8241 | H6: ='FREE CASH FLOW'!I22 -> 5012.9944 | I6: ='FREE CASH FLOW'!J22 -> 5770.987 | J6: ='FREE CASH FLOW'!K22 -> 6643.5923 | K6: ='FREE CASH FLOW'!L22 -> 7648.1404
F7: Discount Factor | G7: =((1/(1+$C$3))^G4) -> 0.92490581 | H7: =((1/(1+$C$3))^H4) -> 0.85545076 | I7: =((1/(1+$C$3))^I4) -> 0.79121138 | J7: =((1/(1+$C$3))^J4) -> 0.731796 | K7: =((1/(1+$C$3))^K4) -> 0.67684238
F8: PV OF FCFF | G8: =G6*G7 -> 7443.4793 | H8: =H6*H7 -> 4288.3699 | I8: =I6*I7 -> 4566.0706 | J8: =J6*J7 -> 4861.7543 | K8: =K6*K7 -> 5176.5855
E11: 1 | F11: TV of PV FCFF | G11: =SUM(G8:K8) -> 26336.26
E12: 2 | F12: Terminal Value( Perpetuity Method) | G12: =((K6*(1+C4))/(C3-C4)) -> 257462.18
E13: 3 | F13: PV of TV | G13: =G12*K7 -> 174261.31
E14: 4 | F14: Enterprise Value | G14: =G11+G13 -> 200597.57
F16: SENSITIVITY ANALYSIS
F18: =G14 -> 200597.57 | G18: 0.08 | H18: 0.09 | I18: 0.1 | J18: 0.11 | K18: 0.12
F19: 0.05 | G19: 208601.01 | H19: 156218.8 | I19: 124808.32 | J19: 103882.77 | K19: 88947.848
F20: 0.06 | G20: 302294.53 | H20: 201369.93 | I20: 150927.24 | J20: 120676.33 | K20: 100520.54
F21: 0.07 | G21: 583375.11 | H21: 291672.19 | I21: 194458.76 | J21: 145866.66 | K21: 116722.31
F22: 0.08 | G22: #DIV/0! | H22: 562578.96 | I22: 281521.81 | J22: 187850.55 | K22: 141024.97
F23: 0.09 | G23: -540947.2 | H23: #DIV/0! | I23: 542710.95 | J23: 271818.34 | K23: 181529.4
